<?xml version="1.0" ?>
<robot name="rmp_bot_036" xmlns:xacro="http://www.ros.org/wiki/xacro">

<xacro:include filename="$(find rrlab_robot_description)/urdf/materials.xacro" />
<xacro:include filename="$(find rrlab_robot_description)/urdf/rmp_bot_036.trans" />
<xacro:include filename="$(find rrlab_robot_description)/urdf/rmp_bot_036.gazebo" />

<link name="base_link">
  <inertial>
    <origin xyz="-0.0001229224289252779 0.0 0.033951078072480476" rpy="0 0 0"/>
    <mass value="0.4740920288945189"/>
    <inertia ixx="0.000417" iyy="0.000828" izz="0.001117" ixy="0.0" iyz="0.0" ixz="-0.0"/>
  </inertial>
  <visual>
    <origin xyz="0 0 0" rpy="0 0 0"/>
    <geometry>
      <mesh filename="package://rrlab_robot_description/meshes/base_link.stl" scale="0.001 0.001 0.001"/>
    </geometry>
    <material name="silver"/>
  </visual>
  <collision>
    <origin xyz="0 0 0" rpy="0 0 0"/>
    <geometry>
      <mesh filename="package://rrlab_robot_description/meshes/base_link.stl" scale="0.001 0.001 0.001"/>
    </geometry>
  </collision>
</link>

<link name="right_wheel_1">
  <inertial>
    <origin xyz="-1.4932499681208355e-14 -0.012500000000000011 0.0" rpy="0 0 0"/>
    <mass value="0.06391177554646729"/>
    <inertia ixx="1.8e-05" iyy="3e-05" izz="1.8e-05" ixy="0.0" iyz="-0.0" ixz="0.0"/>
  </inertial>
  <visual>
    <origin xyz="0.035 0.06 -0.03" rpy="0 0 0"/>
    <geometry>
      <mesh filename="package://rrlab_robot_description/meshes/right_wheel_1.stl" scale="0.001 0.001 0.001"/>
    </geometry>
    <material name="black"/>
  </visual>
  <collision>
    <origin xyz="0.035 0.06 -0.03" rpy="0 0 0"/>
    <geometry>
      <mesh filename="package://rrlab_robot_description/meshes/right_wheel_1.stl" scale="0.001 0.001 0.001"/>
    </geometry>
  </collision>
</link>

<link name="left_wheel_1">
  <inertial>
    <origin xyz="-1.4932499681208355e-14 0.012499999999999997 0.0" rpy="0 0 0"/>
    <mass value="0.06391177554646729"/>
    <inertia ixx="1.8e-05" iyy="3e-05" izz="1.8e-05" ixy="-0.0" iyz="0.0" ixz="0.0"/>
  </inertial>
  <visual>
    <origin xyz="0.035 -0.06 -0.03" rpy="0 0 0"/>
    <geometry>
      <mesh filename="package://rrlab_robot_description/meshes/left_wheel_1.stl" scale="0.001 0.001 0.001"/>
    </geometry>
    <material name="black"/>
  </visual>
  <collision>
    <origin xyz="0.035 -0.06 -0.03" rpy="0 0 0"/>
    <geometry>
      <mesh filename="package://rrlab_robot_description/meshes/left_wheel_1.stl" scale="0.001 0.001 0.001"/>
    </geometry>
  </collision>
</link>

<link name="lidar_1">
  <inertial>
    <origin xyz="5.026061718855929e-18 0.0 0.0049999999999999906" rpy="0 0 0"/>
    <mass value="0.2219535209761188"/>
    <inertia ixx="5.2e-05" iyy="5.2e-05" izz="0.0001" ixy="0.0" iyz="-0.0" ixz="-0.0"/>
  </inertial>
  <visual>
    <origin xyz="-0.0 -0.0 -0.0675" rpy="0 0 0"/>
    <geometry>
      <mesh filename="package://rrlab_robot_description/meshes/lidar_1.stl" scale="0.001 0.001 0.001"/>
    </geometry>
    <material name="silver"/>
  </visual>
  <collision>
    <origin xyz="-0.0 -0.0 -0.0675" rpy="0 0 0"/>
    <geometry>
      <mesh filename="package://rrlab_robot_description/meshes/lidar_1.stl" scale="0.001 0.001 0.001"/>
    </geometry>
  </collision>
</link>

<link name="caster_1">
  <inertial>
    <origin xyz="-0.020000000000000004 -8.041698750169483e-18 -0.0067500000000000095" rpy="0 0 0"/>
    <mass value="0.06936047530503715"/>
    <inertia ixx="5e-06" iyy="5e-06" izz="7e-06" ixy="-0.0" iyz="-0.0" ixz="-0.0"/>
  </inertial>
  <visual>
    <origin xyz="-0.075 -0.0 -0.0175" rpy="0 0 0"/>
    <geometry>
      <mesh filename="package://rrlab_robot_description/meshes/caster_1.stl" scale="0.001 0.001 0.001"/>
    </geometry>
    <material name="silver"/>
  </visual>
  <collision>
    <origin xyz="-0.075 -0.0 -0.0175" rpy="0 0 0"/>
    <geometry>
      <mesh filename="package://rrlab_robot_description/meshes/caster_1.stl" scale="0.001 0.001 0.001"/>
    </geometry>
  </collision>
</link>


<joint name="right_wheel_joint" type="continuous">
  <origin xyz="-0.035 -0.06 0.03" rpy="0 0 0"/>
  <parent link="base_link"/>
  <child link="right_wheel_1"/>
  <axis xyz="0.0 1.0 0.0"/>
</joint>

<joint name="left_wheel_joint" type="continuous">
  <origin xyz="-0.035 0.06 0.03" rpy="0 0 0"/>
  <parent link="base_link"/>
  <child link="left_wheel_1"/>
  <axis xyz="0.0 1.0 0.0"/>
</joint>

<joint name="lidar_joint" type="fixed">
  <origin xyz="0.0 0.0 0.0675" rpy="0 0 0"/>
  <parent link="base_link"/>
  <child link="lidar_1"/>
</joint>

<joint name="caster_joint" type="fixed">
  <origin xyz="0.075 0.0 0.0175" rpy="0 0 0"/>
  <parent link="base_link"/>
  <child link="caster_1"/>
</joint>

</robot>
